<?xml version="1.0" ?>
<!-- =================================================================================== -->
<!-- |    This document was autogenerated by xacro from wb.urdf.xacro                  | -->
<!-- |    EDITING THIS FILE BY HAND IS NOT RECOMMENDED                                 | -->
<!-- =================================================================================== -->
<robot name="wheeled_biped">
  <!-- XACRO DEFINITIONS -->
  <material name="blue">
    <color rgba="0 0 0.8 1"/>
  </material>
  <!-- LINKS DEFINITIONS -->
  <!-- Dummy base link -->
  <link name="base_link"/>
  <joint name="base_to_chassis_joint" type="fixed">
    <parent link="base_link"/>
    <child link="chassis"/>
    <origin rpy="0 0 0" xyz="0 0 0"/>
  </joint>
  <!-- Chassis link -->
  <link name="chassis">
    <inertial>
      <mass value="1.7"/>
      <inertia ixx="0.004604166666666667" ixy="0.0" ixz="0.0" iyy="0.002833333333333334" iyz="0.0" izz="0.004604166666666667"/>
    </inertial>
    <collision name="collision">
      <geometry>
        <box size="0.1 0.15 0.1"/>
      </geometry>
    </collision>
    <visual name="visual">
      <geometry>
        <box size="0.1 0.15 0.1"/>
      </geometry>
    </visual>
    <!-- Orientation indicator box -->
    <visual name="orientation_indicator">
      <origin rpy="0 0 0" xyz="0.025 0 0.060000000000000005"/>
      <geometry>
        <box size="0.025 0.01875 0.02"/>
      </geometry>
    </visual>
  </link>
  <link name="left_hip">
    <!-- Inertial parameters -->
    <inertial>
      <origin rpy="0 0 0" xyz="0 -0.015 -0.0875"/>
      <mass value="0.15"/>
      <inertia ixx="0.00039406249999999994" ixy="0.0" ixz="0.0" iyy="0.00042781249999999997" iyz="0.0" izz="5.624999999999999e-05"/>
    </inertial>
    <!-- Collision geometry -->
    <collision name="left_hip_collision">
      <origin rpy="0 0 0" xyz="0 -0.015 -0.0875"/>
      <geometry>
        <box size="0.06 0.03 0.175"/>
      </geometry>
    </collision>
    <!-- Visual geometry -->
    <visual name="left_hip_visual">
      <origin rpy="0 0 0" xyz="0 -0.015 -0.0875"/>
      <geometry>
        <box size="0.06 0.03 0.175"/>
      </geometry>
    </visual>
  </link>
  <link name="right_hip">
    <!-- Inertial parameters -->
    <inertial>
      <origin rpy="0 0 0" xyz="0 0.015 -0.0875"/>
      <mass value="0.15"/>
      <inertia ixx="0.00039406249999999994" ixy="0.0" ixz="0.0" iyy="0.00042781249999999997" iyz="0.0" izz="5.624999999999999e-05"/>
    </inertial>
    <!-- Collision geometry -->
    <collision name="right_hip_collision">
      <origin rpy="0 0 0" xyz="0 0.015 -0.0875"/>
      <geometry>
        <box size="0.06 0.03 0.175"/>
      </geometry>
    </collision>
    <!-- Visual geometry -->
    <visual name="right_hip_visual">
      <origin rpy="0 0 0" xyz="0 0.015 -0.0875"/>
      <geometry>
        <box size="0.06 0.03 0.175"/>
      </geometry>
    </visual>
  </link>
  <joint name="left_hip_joint" type="revolute">
    <parent link="chassis"/>
    <child link="left_hip"/>
    <origin rpy="0 0 0" xyz="0 -0.075 0"/>
    <axis xyz="0 1 0"/>
    <limit effort="3.8" lower="-3.14159" upper="3.14159" velocity="60.0"/>
  </joint>
  <joint name="right_hip_joint" type="revolute">
    <parent link="chassis"/>
    <child link="right_hip"/>
    <origin rpy="0 0 0" xyz="0 0.075 0"/>
    <axis xyz="0 1 0"/>
    <limit effort="3.8" lower="-3.14159" upper="3.14159" velocity="60.0"/>
  </joint>
  <link name="left_knee">
    <!-- Inertial parameters -->
    <inertial>
      <origin rpy="0 0 0" xyz="0 0 -0.0875"/>
      <mass value="0.05"/>
      <inertia ixx="0.00012854166666666664" ixy="0.0" ixz="0.0" iyy="0.0001316083333333333" iyz="0.0" izz="4.941666666666666e-06"/>
    </inertial>
    <!-- Collision geometry -->
    <collision name="left_knee_collision">
      <origin rpy="0 0 0" xyz="0 0 -0.0875"/>
      <geometry>
        <box size="0.031 0.015 0.175"/>
      </geometry>
    </collision>
    <!-- Visual geometry -->
    <visual name="left_knee_visual">
      <origin rpy="0 0 0" xyz="0 0 -0.0875"/>
      <geometry>
        <box size="0.031 0.015 0.175"/>
      </geometry>
    </visual>
  </link>
  <link name="right_knee">
    <!-- Inertial parameters -->
    <inertial>
      <origin rpy="0 0 0" xyz="0 0 -0.0875"/>
      <mass value="0.05"/>
      <inertia ixx="0.00012854166666666664" ixy="0.0" ixz="0.0" iyy="0.0001316083333333333" iyz="0.0" izz="4.941666666666666e-06"/>
    </inertial>
    <!-- Collision geometry -->
    <collision name="right_knee_collision">
      <origin rpy="0 0 0" xyz="0 0 -0.0875"/>
      <geometry>
        <box size="0.031 0.015 0.175"/>
      </geometry>
    </collision>
    <!-- Visual geometry -->
    <visual name="right_knee_visual">
      <origin rpy="0 0 0" xyz="0 0 -0.0875"/>
      <geometry>
        <box size="0.031 0.015 0.175"/>
      </geometry>
    </visual>
  </link>
  <joint name="left_knee_joint" type="revolute">
    <parent link="left_hip"/>
    <child link="left_knee"/>
    <origin rpy="0 0 0" xyz="0 -0.015 -0.175"/>
    <axis xyz="0 1 0"/>
    <limit effort="3.8" lower="-3.14159" upper="3.14159" velocity="60.0"/>
  </joint>
  <joint name="right_knee_joint" type="revolute">
    <parent link="right_hip"/>
    <child link="right_knee"/>
    <origin rpy="0 0 0" xyz="0 0.015 -0.175"/>
    <axis xyz="0 1 0"/>
    <limit effort="3.8" lower="-3.14159" upper="3.14159" velocity="60.0"/>
  </joint>
  <link name="left_wheel">
    <!-- Inertial parameters -->
    <inertial>
      <origin rpy="1.5708 0 0" xyz="0 -0.02345 0"/>
      <mass value="0.7"/>
      <inertia ixx="0.0007583105833333331" ixy="0.0" ixz="0.0" iyy="0.0007583105833333331" iyz="0.0" izz="0.0012599999999999998"/>
    </inertial>
    <!-- Collision geometry -->
    <collision name="left_wheel_collision">
      <origin rpy="1.5708 0 0" xyz="0 -0.02345 0"/>
      <geometry>
        <cylinder length="0.0469" radius="0.06"/>
      </geometry>
    </collision>
    <!-- Visual geometry -->
    <visual name="left_wheel_visual">
      <origin rpy="1.5708 0 0" xyz="0 -0.02345 0"/>
      <geometry>
        <cylinder length="0.0469" radius="0.06"/>
      </geometry>
    </visual>
    <visual name="left_wheel_marker">
      <origin rpy="0 0 0" xyz="0 0 0.06"/>
      <geometry>
        <box size="0.02 0.001 0.06"/>
      </geometry>
      <material name="red">
        <color rgba="1 0 0 1"/>
      </material>
    </visual>
  </link>
  <link name="right_wheel">
    <!-- Inertial parameters -->
    <inertial>
      <origin rpy="1.5708 0 0" xyz="0 0.02345 0"/>
      <mass value="0.7"/>
      <inertia ixx="0.0007583105833333331" ixy="0.0" ixz="0.0" iyy="0.0007583105833333331" iyz="0.0" izz="0.0012599999999999998"/>
    </inertial>
    <!-- Collision geometry -->
    <collision name="right_wheel_collision">
      <origin rpy="1.5708 0 0" xyz="0 0.02345 0"/>
      <geometry>
        <cylinder length="0.0469" radius="0.06"/>
      </geometry>
    </collision>
    <!-- Visual geometry -->
    <visual name="right_wheel_visual">
      <origin rpy="1.5708 0 0" xyz="0 0.02345 0"/>
      <geometry>
        <cylinder length="0.0469" radius="0.06"/>
      </geometry>
    </visual>
    <visual name="right_wheel_marker">
      <origin rpy="0 0 0" xyz="0 0 0.06"/>
      <geometry>
        <box size="0.02 0.001 0.06"/>
      </geometry>
      <material name="red">
        <color rgba="1 0 0 1"/>
      </material>
    </visual>
  </link>
  <joint name="left_wheel_joint" type="continuous">
    <parent link="left_knee"/>
    <child link="left_wheel"/>
    <origin rpy="0 0 0" xyz="0 -0.0075 -0.175"/>
    <axis xyz="0 1 0"/>
    <limit effort="3.8" velocity="60.0"/>
    <dynamics damping="0.005" friction="0"/>
  </joint>
  <joint name="right_wheel_joint" type="continuous">
    <parent link="right_knee"/>
    <child link="right_wheel"/>
    <origin rpy="0 0 0" xyz="0 0.0075 -0.175"/>
    <axis xyz="0 1 0"/>
    <limit effort="3.8" velocity="60.0"/>
    <dynamics damping="0.005" friction="0"/>
  </joint>
  <!-- IMU link -->
  <link name="imu_link">
    <inertial>
      <mass value="0.01"/>
      <origin rpy="0 0 0" xyz="0 0 0"/>
      <!-- approximate a small cube -->
      <inertia ixx="1e-6" ixy="0.0" ixz="0.0" iyy="1e-6" iyz="0.0" izz="1e-6"/>
    </inertial>
    <visual>
      <origin rpy="0 0 0" xyz="0 0 0"/>
      <geometry>
        <box size="0.02 0.02 0.02"/>
      </geometry>
      <material name="blue"/>
    </visual>
  </link>
  <!--Joint IMU to the chassis -->
  <joint name="imu_joint" type="fixed">
    <parent link="chassis"/>
    <child link="imu_link"/>
    <!-- adjust offset to position the IMU where you like: -->
    <origin rpy="0 0 0" xyz="0 0 0.02"/>
  </joint>
</robot>
