#VRML_SIM R2025a utf8

EXTERNPROTO "https://raw.githubusercontent.com/cyberbotics/webots/R2025a/projects/objects/backgrounds/protos/TexturedBackground.proto"
EXTERNPROTO "https://raw.githubusercontent.com/cyberbotics/webots/R2025a/projects/objects/backgrounds/protos/TexturedBackgroundLight.proto"
EXTERNPROTO "https://raw.githubusercontent.com/cyberbotics/webots/R2025a/projects/objects/floors/protos/RectangleArena.proto"

WorldInfo {
}
Viewpoint {
  orientation 0.27129331856849376 -0.251991353088137 -0.928924266702568 4.565377850701826
  position -0.08707525839983397 -0.5552677598741748 0.5121730364761664
}
TexturedBackground {
}
TexturedBackgroundLight {
}
RectangleArena {
  floorSize 3 3
}
Robot {
  translation -0.07571248358101328 0.03999870020132294 0.050427462730269275
  rotation 2.1450092987220026e-07 -0.9999999999999555 2.071331754270357e-07 1.5953191795170552
  children [
    InertialUnit {
      translation 0 0 0.065
      children [
        Shape {
          appearance PBRAppearance {
            baseColor 0.560784 0.941176 0.643137
          }
          geometry Box {
            size 0.03 0.03 0.03
          }
        }
      ]
    }
    Solid {
      children [
        Shape {
          appearance PBRAppearance {
            baseColor 0.5 0.5 0.5
            roughness 1
            metalness 0
          }
          geometry Box {
            size 0.1 0.15 0.1
          }
        }
        Pose {
          translation 0.025 0 0.06
          children [
            Shape {
              appearance PBRAppearance {
                baseColor 0.5 0.5 0.5
                roughness 1
                metalness 0
              }
              geometry Box {
                size 0.025 0.01875 0.02
              }
            }
          ]
        }
        HingeJoint {
          jointParameters HingeJointParameters {
            position -3.563016124101411e-07
            axis 0 1 0
            anchor 0 -0.075 0
          }
          device [
            RotationalMotor {
              name "left_hip_joint"
              maxVelocity 60
              minPosition -3.14159
              maxPosition 3.14159
              maxTorque 3.8
            }
            PositionSensor {
              name "left_hip_joint_sensor"
            }
          ]
          endPoint Solid {
            translation 0 -0.075 0
            rotation 0 -0.9999999999999999 0 3.5638394186202926e-07
            children [
              Pose {
                translation 0 -0.015 -0.0875
                children [
                  Shape {
                    appearance PBRAppearance {
                      baseColor 0.5 0.5 0.5
                      roughness 1
                      metalness 0
                    }
                    geometry Box {
                      size 0.06 0.03 0.175
                    }
                  }
                ]
              }
              HingeJoint {
                jointParameters HingeJointParameters {
                  position -4.834092631150619e-07
                  axis 0 1 0
                  anchor 0 -0.015 -0.175
                }
                device [
                  RotationalMotor {
                    name "left_knee_joint"
                    maxVelocity 60
                    minPosition -3.14159
                    maxPosition 3.14159
                    maxTorque 3.8
                  }
                  PositionSensor {
                    name "left_knee_joint_sensor"
                  }
                ]
                endPoint Solid {
                  translation 0 -0.015 -0.175
                  rotation 0 -1 0 4.833124500580697e-07
                  children [
                    Pose {
                      translation 0 0 -0.0875
                      children [
                        Shape {
                          appearance PBRAppearance {
                            baseColor 0.5 0.5 0.5
                            roughness 1
                            metalness 0
                          }
                          geometry Box {
                            size 0.031 0.015 0.175
                          }
                        }
                      ]
                    }
                    HingeJoint {
                      jointParameters HingeJointParameters {
                        position 1.1205230714829541e-08
                        axis 0 1 0
                        anchor 0 -0.0075 -0.175
                        dampingConstant 0.005
                      }
                      device [
                        RotationalMotor {
                          name "left_wheel_joint"
                          maxVelocity 60
                          maxTorque 3.8
                        }
                        PositionSensor {
                          name "left_wheel_joint_sensor"
                        }
                      ]
                      endPoint Solid {
                        translation 0 -0.0075 -0.175
                        rotation 0 1 0 0
                        children [
                          Pose {
                            translation 0 -0.02345 0
                            rotation 1 0 0 1.5708
                            children [
                              Shape {
                                appearance PBRAppearance {
                                  baseColor 0.5 0.5 0.5
                                  roughness 1
                                  metalness 0
                                }
                                geometry Cylinder {
                                  height 0.0469
                                  radius 0.06
                                }
                              }
                            ]
                          }
                          Pose {
                            translation 0 0 0.06
                            children [
                              Shape {
                                appearance DEF red PBRAppearance {
                                  baseColor 1 0 0
                                  roughness 1
                                  metalness 0
                                }
                                geometry Box {
                                  size 0.02 0.001 0.06
                                }
                              }
                            ]
                          }
                        ]
                        name "left_wheel"
                        boundingObject Pose {
                          translation 0 -0.02345 0
                          rotation 1 0 0 1.5708
                          children [
                            Cylinder {
                              height 0.0469
                              radius 0.06
                            }
                          ]
                        }
                        physics Physics {
                          density -1
                          mass 0.7
                        }
                        linearVelocity 7.032580752718296e-08 1.6986367618014353e-11 4.1563385056581194e-10
                        angularVelocity -1.1106586493838094e-11 1.2182680610529738e-06 5.922406605563502e-10
                      }
                    }
                  ]
                  name "left_knee"
                  boundingObject Pose {
                    translation 0 0 -0.0875
                    children [
                      Box {
                        size 0.031 0.015 0.175
                      }
                    ]
                  }
                  physics Physics {
                    density -1
                    mass 0.5
                  }
                  linearVelocity 6.157187493394112e-08 1.3932570888691058e-11 1.0702029072717778e-07
                  angularVelocity -9.216259331018023e-12 1.2186116151899632e-06 4.4937496916985005e-10
                }
              }
            ]
            name "left_hip"
            boundingObject Pose {
              translation 0 -0.015 -0.0875
              children [
                Box {
                  size 0.06 0.03 0.175
                }
              ]
            }
            physics Physics {
              density -1
              mass 0.15
            }
            linearVelocity 5.605598654886043e-08 -1.253973249140166e-11 8.276950917244601e-08
            angularVelocity -6.174919335750251e-12 -1.4961565111687024e-06 2.6759675290288767e-10
          }
        }
        HingeJoint {
          jointParameters HingeJointParameters {
            position -3.5607595828976224e-07
            axis 0 1 0
            anchor 0 0.075 0
          }
          device [
            RotationalMotor {
              name "right_hip_joint"
              maxVelocity 60
              minPosition -3.14159
              maxPosition 3.14159
              maxTorque 3.8
            }
            PositionSensor {
              name "right_hip_joint_sensor"
            }
          ]
          endPoint Solid {
            translation 0 0.075 0
            rotation 0 -1 0 3.5638394186202926e-07
            children [
              Pose {
                translation 0 0.015 -0.0875
                children [
                  Shape {
                    appearance PBRAppearance {
                      baseColor 0.5 0.5 0.5
                      roughness 1
                      metalness 0
                    }
                    geometry Box {
                      size 0.06 0.03 0.175
                    }
                  }
                ]
              }
              HingeJoint {
                jointParameters HingeJointParameters {
                  position -4.831496885767144e-07
                  axis 0 1 0
                  anchor 0 0.015 -0.175
                }
                device [
                  RotationalMotor {
                    name "right_knee_joint"
                    maxVelocity 60
                    minPosition -3.14159
                    maxPosition 3.14159
                    maxTorque 3.8
                  }
                  PositionSensor {
                    name "right_knee_joint_sensor"
                  }
                ]
                endPoint Solid {
                  translation 0 0.015 -0.175
                  rotation 0 -1 0 4.833124500580697e-07
                  children [
                    Pose {
                      translation 0 0 -0.0875
                      children [
                        Shape {
                          appearance PBRAppearance {
                            baseColor 0.5 0.5 0.5
                            roughness 1
                            metalness 0
                          }
                          geometry Box {
                            size 0.031 0.015 0.175
                          }
                        }
                      ]
                    }
                    HingeJoint {
                      jointParameters HingeJointParameters {
                        position -4.4750064499595257e-07
                        axis 0 1 0
                        anchor 0 0.0075 -0.175
                        dampingConstant 0.005
                      }
                      device [
                        RotationalMotor {
                          name "right_wheel_joint"
                          maxVelocity 60
                          maxTorque 3.8
                        }
                        PositionSensor {
                          name "right_wheel_joint_sensor"
                        }
                      ]
                      endPoint Solid {
                        translation 0 0.0075 -0.175
                        rotation 0 -1 0 4.4703483581543064e-07
                        children [
                          Pose {
                            translation 0 0.02345 0
                            rotation 1 0 0 1.5708
                            children [
                              Shape {
                                appearance PBRAppearance {
                                  baseColor 0.5 0.5 0.5
                                  roughness 1
                                  metalness 0
                                }
                                geometry Cylinder {
                                  height 0.0469
                                  radius 0.06
                                }
                              }
                            ]
                          }
                          Pose {
                            translation 0 0 0.06
                            children [
                              Shape {
                                appearance USE red
                                geometry Box {
                                  size 0.02 0.001 0.06
                                }
                              }
                            ]
                          }
                        ]
                        name "right_wheel"
                        boundingObject Pose {
                          translation 0 0.02345 0
                          rotation 1 0 0 1.5708
                          children [
                            Cylinder {
                              height 0.0469
                              radius 0.06
                            }
                          ]
                        }
                        physics Physics {
                          density -1
                          mass 0.7
                        }
                        linearVelocity 7.03258795853061e-08 -1.624432344661711e-11 4.1618968177638537e-10
                        angularVelocity -1.3686884040844072e-12 1.2182695332818957e-06 -5.923173390610384e-10
                      }
                    }
                  ]
                  name "right_knee"
                  boundingObject Pose {
                    translation 0 0 -0.0875
                    children [
                      Box {
                        size 0.031 0.015 0.175
                      }
                    ]
                  }
                  physics Physics {
                    density -1
                    mass 0.5
                  }
                  linearVelocity 6.157190453326411e-08 -1.3224974102838588e-11 1.0702134176199252e-07
                  angularVelocity -3.4649253513689274e-12 1.218613105147712e-06 -4.494558117642763e-10
                }
              }
            ]
            name "right_hip"
            boundingObject Pose {
              translation 0 0.015 -0.0875
              children [
                Box {
                  size 0.06 0.03 0.175
                }
              ]
            }
            physics Physics {
              density -1
              mass 0.15
            }
            linearVelocity 5.6056003502336086e-08 1.3199039181138855e-11 8.276958666897372e-08
            angularVelocity -3.890579447138668e-12 -1.496169225163982e-06 -2.676834532708347e-10
          }
        }
      ]
      name "chassis"
      boundingObject Box {
        size 0.1 0.15 0.1
      }
      physics Physics {
        density -1
        mass 1.7
      }
    }
  ]
  name "wb"
  boundingObject Box {
    size 0.1 0.15 0.1
  }
  physics Physics {
    density -1
    mass 0.1
  }
  synchronization FALSE
  linearVelocity 5.3153678394719415e-08 3.155965559921606e-13 -4.807394597358262e-08
  angularVelocity -6.140487638093635e-12 9.845514384492715e-07 -3.9496781273295245e-14
}
